Workbook

Sheet Visualization
A1: Date | B1: Litre
A2: 45292 | B2: 2.250526
A3: 45293 | B3: 2.1550271
A4: 45294 | B4: 2.2006895
A5: 45295 | B5: 2.1085771
A6: 45296 | B6: 2.2832906
A7: 45297 | B7: 1.6966565
A8: 45298 | B8: 1.6188466
A9: 45299 | B9: 2.2397975
A10: 45300 | B10: 2.2667257
A11: 45301 | B11: 2.2791504
A12: 45302 | B12: 2.2706708
A13: 45303 | B13: 2.2233255
... A50: 45340 | B50: 1.5329352

Sheet Demo
B2: Company Goal: Product Manager wants to buid a product to help our students track their progress w.r.t course
B3: Why to prioritise this product as you might be engaged with some other work?
C4: Vision | D4: Business Priority | F4: Enagagement & Completion Rate will increase to put in more efforts
D5: (How urgent it is, whats the end goal)
B7: The first step is to "DEFINE THE PROBLEM"
C8: All we know is what product manager wants. How and what more info you will fetch?
C9: so, we need some metrics to define the "PROGRESS" of the candidates.
B11: What progress to track?
C12: Student's progress towards data competency
B14: What is data competency?
C15: Achieving a certain skill level in all the analysis stages with a data tool
B17: How will student achieve this data competency?
B18: 1. Effort (By putting in the hours & doing practise)
B19: 2. Achieving the skill level in each stages and tool
B21: We have to help candidate to track their Progress in terms of efforts by determining:
C22: a. Time reqiured to be dedicated
C23: b. Actual time spent
B24: Thus, we can also say: | E24: DVA
C25: a. Goal: | D25: 150 hours | E25: 100 hrs | F25: ACTUAL vs. ACHIEVED ANALYSIS
C26: b. Time: | D26: 58 days | E26: 20
C27: Thus, Daily hours to dedicate: | F27: =150/58 -> 2.5862069 | G27: daily
B30: Total Days | C30: 58
B31: Days Elasped | C31: 1 | D31: (Let's Say)
B32: Thus, Days Left | C32: 57 | F32: Unit: | G32: hours/day
J33: TARGET VS. ACTUAL ANALYSIS
C34: Hours spent | F34: Dates | G34: hours spent
B35: Actual hours completed | C35: 3 | D35: (Let's say) | F35: 45566 | G35: 1 | K35: How much are we studying per day? | L35: How much should we study per day to achieve our goal?
B36: Expected hours | C36: 2.6 | F36: 45567 | G36: 1
B37: Progress | C37: =C35/C36 -> 1.1538462 | F37: 45568
B38: Remark | C38: you are doing well! | F38: 45569 | I38: Goal (hrs) | J38: Average(hrs)
F39: Total | G39: =SUM($G$35:$G$38) -> 2 | I39: 12 | J39: =I39/COUNT($F$35:$F$38) -> 3 | K39: =$G$39 -> 2 | L39: =K43/K44 -> 5
J40: target | K40: actual
F41: For 4 days data, you need to cover 12 hours
F42: in total, i.e. daily dedicate 3 hrs. | I42: Thus, from the above dates table: | J42: Days Done | K42: =COUNT($G$35:$G$38) -> 2
J43: Hours left | K43: =$I$39-$G$39 -> 10
J44: Days left | K44: =COUNTBLANK($G$35:$G$38) -> 2
H46: 25 | I46: Low | K46: 0.25 | L46: Beginner
H47: 50 | I47: Medium | K47: 0.5 | L47: Intermediate
B48: Progress in terms of skill level | H48: 100 | I48: High | K48: 0.9 | L48: Expert
C49: Level | D49: Scores | F49: Example: | O49: =SUM($G$51:$G$58)/ (COUNTA($H$51:$H$58)*100) -> 0.57142857
...

Sheet Excel Syllabus Data
A1: Category | B1: Topic | C1: Concepts | D1: Level of Understanding | E1: Score
A2: Intro to Excel | B2: Excel for Analytics | C2: Excels' role in each of the analysis stages | D2: High | E2: =_xlfn.IFNA( VLOOKUP($D2, 'Goals Data'!$A$8:$B$11, 2, 0),"") -> 100 | G2: 1. Add level of understanding of the topics in column D as:
B3: Excel terminologies | C3: Workbook, worksheets, rows, columns, cells, and ranges | D3: High | E3: =_xlfn.IFNA( VLOOKUP($D3, 'Goals Data'!$A$8:$B$11, 2, 0),"") -> 100 | H3: Low, Medium, High through Data validations
B4: Excel Shortcut Keys | C4: Commonly used shortcut keys | D4: High | E4: =_xlfn.IFNA( VLOOKUP($D4, 'Goals Data'!$A$8:$B$11, 2, 0),"") -> 100
A5: Data Gathering | B5: Structured Data | C5: What is structured data? | D5: High | E5: =_xlfn.IFNA( VLOOKUP($D5, 'Goals Data'!$A$8:$B$11, 2, 0),"") -> 100 | G5: 2. Highlight low as red, medium as yellow & high as green
B6: Importing Data | C6: Using Get data feature | E6: =_xlfn.IFNA( VLOOKUP($D6, 'Goals Data'!$A$8:$B$11, 2, 0),"")
C7: Handling JSON | E7: =_xlfn.IFNA( VLOOKUP($D7, 'Goals Data'!$A$8:$B$11, 2, 0),"") | G7: 3. Assign Scores based on your level of understanding in column E
B8: Data Types | C8: Text/String, Number, Date, Boolean, Error | D8: High | E8: =_xlfn.IFNA( VLOOKUP($D8, 'Goals Data'!$A$8:$B$11, 2, 0),"") -> 100
B9: Data Validation | C9: Restricting data entries for data correctness | D9: High | E9: =_xlfn.IFNA( VLOOKUP($D9, 'Goals Data'!$A$8:$B$11, 2, 0),"") -> 100
C10: Custom data validations | D10: Medium | E10: =_xlfn.IFNA( VLOOKUP($D10, 'Goals Data'!$A$8:$B$11, 2, 0),"") -> 50
C11: Remove Duplicates (Dealing with Duplicates) | D11: Medium | E11: =_xlfn.IFNA( VLOOKUP($D11, 'Goals Data'!$A$8:$B$11, 2, 0),"") -> 50
C12: Transpose | D12: Medium | E12: =_xlfn.IFNA( VLOOKUP($D12, 'Goals Data'!$A$8:$B$11, 2, 0),"") -> 50
C13: Text to Columns | D13: High | E13: =_xlfn.IFNA( VLOOKUP($D13, 'Goals Data'!$A$8:$B$11, 2, 0),"") -> 100
A14: Data Preparation | B14: Formatting | C14: What is formatting? | D14: High | E14: =_xlfn.IFNA( VLOOKUP($D14, 'Goals Data'!$A$8:$B$11, 2, 0),"") -> 100
C15: Various formatting options (Text Font, Text Alignment etc..) | D15: High | E15: =_xlfn.IFNA( VLOOKUP($D15, 'Goals Data'!$A$8:$B$11, 2, 0),"") -> 100
C16: Number formatting | D16: Medium | E16: =_xlfn.IFNA( VLOOKUP($D16, 'Goals Data'!$A$8:$B$11, 2, 0),"") -> 50
C17: Custom number formats | D17: Medium | E17: =_xlfn.IFNA( VLOOKUP($D17, 'Goals Data'!$A$8:$B$11, 2, 0),"") -> 50
C18: Date & Time Formatting | D18: Medium | E18: =_xlfn.IFNA( VLOOKUP($D18, 'Goals Data'!$A$8:$B$11, 2, 0),"") -> 50
C19: Custom Date & Time formats | D19: High | E19: =_xlfn.IFNA( VLOOKUP($D19, 'Goals Data'!$A$8:$B$11, 2, 0),"") -> 100
C20: Grouping-UnGrouping | D20: Low | E20: =_xlfn.IFNA( VLOOKUP($D20, 'Goals Data'!$A$8:$B$11, 2, 0),"") -> 25
B21: Conditional Formatting | C21: Basic conditional formatting options | D21: Medium | E21: =_xlfn.IFNA( VLOOKUP($D21, 'Goals Data'!$A$8:$B$11, 2, 0),"") -> 50
C22: Custom conditional formatting | D22: Low | E22: =_xlfn.IFNA( VLOOKUP($D22, 'Goals Data'!$A$8:$B$11, 2, 0),"") -> 25
B23: Paste Special | C23: Copy-paste-paste special | D23: Low | E23: =_xlfn.IFNA( VLOOKUP($D23, 'Goals Data'!$A$8:$B$11, 2, 0),"") -> 25
B24: Sort and Filter | C24: Quick sort | D24: Low | E24: =_xlfn.IFNA( VLOOKUP($D24, 'Goals Data'!$A$8:$B$11, 2, 0),"") -> 25
C25: Custom sort | D25: Medium | E25: =_xlfn.IFNA( VLOOKUP($D25, 'Goals Data'!$A$8:$B$11, 2, 0),"") -> 50
C26: Filters | D26: High | E26: =_xlfn.IFNA( VLOOKUP($D26, 'Goals Data'!$A$8:$B$11, 2, 0),"") -> 100
B27: Cell References | C27: Relative | D27: Medium | E27: =_xlfn.IFNA( VLOOKUP($D27, 'Goals Data'!$A$8:$B$11, 2, 0),"") -> 50
C28: Absolute | E28: =_xlfn.IFNA( VLOOKUP($D28, 'Goals Data'!$A$8:$B$11, 2, 0),"")
B29: Text / string functions | C29: TEXTBEFORE | E29: =_xlfn.IFNA( VLOOKUP($D29, 'Goals Data'!$A$8:$B$11, 2, 0),"")
C30: TEXTAFTER | E30: =_xlfn.IFNA( VLOOKUP($D30, 'Goals Data'!$A$8:$B$11, 2, 0),"")
C31: LEFT | E31: =_xlfn.IFNA( VLOOKUP($D31, 'Goals Data'!$A$8:$B$11, 2, 0),"")
C32: RIGHT | E32: =_xlfn.IFNA( VLOOKUP($D32, 'Goals Data'!$A$8:$B$11, 2, 0),"")
C33: MID | E33: =_xlfn.IFNA( VLOOKUP($D33, 'Goals Data'!$A$8:$B$11, 2, 0),"")
C34: CONCATENATE | E34: =_xlfn.IFNA( VLOOKUP($D34, 'Goals Data'!$A$8:$B$11, 2, 0),"")
C35: TRIM | E35: =_xlfn.IFNA( VLOOKUP($D35, 'Goals Data'!$A$8:$B$11, 2, 0),"")
C36: SUBSTITUTE | E36: =_xlfn.IFNA( VLOOKUP($D36, 'Goals Data'!$A$8:$B$11, 2, 0),"")
C37: VALUE | E37: =_xlfn.IFNA( VLOOKUP($D37, 'Goals Data'!$A$8:$B$11, 2, 0),"")
C38: TEXT | E38: =_xlfn.IFNA( VLOOKUP($D38, 'Goals Data'!$A$8:$B$11, 2, 0),"")
A39: Data Analysis | B39: Logical functions | C39: IF | E39: =_xlfn.IFNA( VLOOKUP($D39, 'Goals Data'!$A$8:$B$11, 2, 0),"")
C40: AND, OR | E40: =_xlfn.IFNA( VLOOKUP($D40, 'Goals Data'!$A$8:$B$11, 2, 0),"")
...

Sheet Goals Data
A2: Study Goal
A3: Target Hours | B3: 130
A4: Available Days | B4: =COUNT('Study Hours Data'!$A$2:$A$33) -> 32 | C4: no. of days you are considering( from study hours sheet, column A)
A5: Daily Goal Hours | B5: =$B$3/$B$4 -> 4.0625 | C5: Avg. hours to be dedicated daily = B3/B4
A8: Level of Understanding | B8: Score
A9: Low | B9: 25
A10: Medium | B10: 50
A11: High | B11: 100
A14: Rank | B14: Score
A15: 0 | B15: Uninitiated
A16: 0.25 | B16: Rookie
A17: 0.5 | B17: Skilled
A18: 0.9 | B18: Professional
A19: 1 | B19: Legendary

Sheet Progress Summary
A2: Study Hours
A3: Day Count | B3: Total Available | C3: =COUNT('Study Hours Data'!$A$2:$A$33) -> 32 | D3: =COUNTA('Study Hours Data'!$A$2:$A$33) | G3: custom formatting to add "days" at the end
B4: Elapsed | C4: =COUNT('Study Hours Data'!$B$2:$B$33) -> 18 | D4: =COUNTA('Study Hours Data'!$B$2:$B$33)
B5: Remaining | C5: =$C$3-$C$4 -> 14 | D5: =C3-C4
A6: Study Hours | B6: Actual (Total hours studied till now) | C6: =SUM('Study Hours Data'!$B$2:$B$33) -> 50 | D6: = SUM('Study Hours Data'!$B$2:$B$33)
B7: Expected (Total hours that should have been done) | C7: ='Goals Data'!$B$5*$C$4 -> 73.125 | D7: =C4*'Goals Data'!B5
B8: Deficit (Hours to cover up) | C8: =$C$7-$C$6 -> 23.125 | D8: =C7 - C6
A9: Daily Average | B9: Current | C9: =$C$6/$C$4 -> 2.7777778 | D9: =Actual hours covered till now / no. of days studied--->C6/C4 | H9: Custom format to add "Hours" at the end
B10: Updated | C10: =('Goals Data'!$B$3 - $C$6)/$C$5 -> 5.7142857 | D10: =(Total hours - Actual Hours completed)/ remaining days
A11: Projections | B11: Total hours I'll complete at this rate (by module end) | C11: =$C$9*$C$3 -> 88.888889 | D11: = Available days * Current daily average----> 32* C9
A12: Current Status | B12: {=_xlfn.IFS($C$10 = 'Goals Data'!$B$5, "You are on track!", $C$10 < 'Goals Data'!$B$5, "Well done! You are ahead of the target", $C$10 > 'Goals Data'!$B$5, "You can do better!")} -> You can do better! | D12: =IFS(C10='Goals Data'!B5,"You're on track!",C10>'Goals Data'!B5,"At this rate, you'll have to spend "&ROUND(C10,2)&" hours daily!",C10<'Goals Data'!B5,"You can do better.")
A13: Data Competency: Excel | E13: Then do conditional formatting base on keyword as:
F14: better---> red, track ---> green , rate--->yellow
A15: Overall | B15: Coverage | C15: =COUNT('Excel Syllabus Data'!$E$2:$E$114) / COUNTA('Excel Syllabus Data'!$C$2:$C$114) -> 0.21238938 | D15: =COUNTA('Excel Syllabus Data'!D2:D102)/COUNTA('Excel Syllabus Data'!C2:C102)
B16: Mastery | C16: =SUM('Excel Syllabus Data'!$E$2:$E$114) / ( COUNTA('Excel Syllabus Data'!$D$2:$D$114)*100) -> 0.6875 | D16: =IF(SUM('Excel Syllabus Data'!E2:E102)=0,0,SUM('Excel Syllabus Data'!E2:E102)/(100*COUNT('Excel Syllabus Data'!E2:E102)))
B17: Rank | C17: =VLOOKUP($C$16, 'Goals Data'!$A$14:$B$19, 2, 1) -> Skilled | D17: =IF(C16="","Uninitiated",VLOOKUP(C16,'Goals Data'!$A$15:$B$18,2,1))
D18: Add data bars for coverage & mastry and give text colors to rank such as legendry black, rookie yellow etc…
A21: Skill Wise Breakdown
A22: Data Gathering | B22: Coverage | C22: =COUNT('Excel Syllabus Data'!$E$5:$E$13)/ COUNTA('Excel Syllabus Data'!$C$5:$C$13) -> 0.77777778
B23: Mastery | C23: =SUM('Excel Syllabus Data'!$E$5:$E$13) / (COUNTA('Excel Syllabus Data'!$C$5:$C$13)*100) -> 0.61111111
B24: Rank | C24: =VLOOKUP($C$23, 'Goals Data'!$A$14:$B$19, 2, 1) -> Skilled
A25: Data Preparation | B25: Coverage
B26: Mastery
B27: Rank
A28: Data Analysis | B28: Coverage
B29: Mastery
B30: Rank
A31: Data Visualization | B31: Coverage
B32: Mastery
B33: Rank
A35: Day Level Average
A36: Day | B36: Total Study Hours | C36: No of Day Elapsed | D36: Average Study Hours
A37: Monday | B37: =SUMIFS('Study Hours Data'!$B$2:$B$33, 'Study Hours Data'!$F$2:$F$33, A37) -> 8 | C37: =COUNTIFS('Study Hours Data'!$F$1:$F$33,A37) -> 3 | D37: =B37/C37 -> 2.6666667
A38: Tuesday | B38: =SUMIFS('Study Hours Data'!$B$2:$B$33, 'Study Hours Data'!$F$2:$F$33, A38) -> 13 | C38: =COUNTIFS('Study Hours Data'!$F$1:$F$33,A38) -> 3 | D38: =B38/C38 -> 4.3333333
A39: Wednesday | B39: =SUMIFS('Study Hours Data'!$B$2:$B$33, 'Study Hours Data'!$F$2:$F$33, A39) -> 7 | C39: =COUNTIFS('Study Hours Data'!$F$1:$F$33,A39) -> 3 | D39: =B39/C39 -> 2.3333333
A40: Thursday | B40: =SUMIFS('Study Hours Data'!$B$2:$B$33, 'Study Hours Data'!$F$2:$F$33, A40) -> 6 | C40: =COUNTIFS('Study Hours Data'!$F$1:$F$33,A40) -> 3 | D40: =B40/C40 -> 2
A41: Friday | B41: =SUMIFS('Study Hours Data'!$B$2:$B$33, 'Study Hours Data'!$F$2:$F$33, A41) -> 3 | C41: =COUNTIFS('Study Hours Data'!$F$1:$F$33,A41) -> 2 | D41: =B41/C41 -> 1.5
A42: Saturday | B42: =SUMIFS('Study Hours Data'!$B$2:$B$33, 'Study Hours Data'!$F$2:$F$33, A42) -> 8 | C42: =COUNTIFS('Study Hours Data'!$F$1:$F$33,A42) -> 2 | D42: =B42/C42 -> 4
A43: Sunday | B43: =SUMIFS('Study Hours Data'!$B$2:$B$33, 'Study Hours Data'!$F$2:$F$33, A43) -> 5 | C43: =COUNTIFS('Study Hours Data'!$F$1:$F$33,A43) -> 2 | D43: =B43/C43 -> 2.5
B45: =SUMIFS('Study Hours Data'!$B$2:$B$33,'Study Hours Data'!$F$2:$F$33, A37) | C45: =COUNTIF('Study Hours Data'!$F$2:$F$33, A37) | D45: =B37/C37
...

Sheet Study Hours Data
A1: Date | B1: Daily Hours Spent | C1: Total hours spent | D1: Target | E1: Day number | F1: Day name
A2: 45558 | B2: 5 | C2: 5 | D2: ='Goals Data'!$B$3 -> 130 | E2: =WEEKDAY(A2) -> 2 | F2: =IF(C2 = 0, "", TEXT(A2, "dddd")) -> Monday | H2: Q: Find the total hours spent in column C
A3: 45559 | B3: 6 | C3: =IF( ISBLANK($B3),0, B3+C2) -> 11 | D3: ='Goals Data'!$B$3 -> 130 | E3: =WEEKDAY(A3) -> 3 | F3: =IF(C3 = 0, "", TEXT(A3, "dddd")) -> Tuesday | I3: [ hint: Cummulative sum of hours]
A4: 45560 | B4: 0 | C4: =IF( ISBLANK($B4),0, B4+C3) -> 11 | D4: ='Goals Data'!$B$3 -> 130 | E4: =WEEKDAY(A4) -> 4 | F4: =IF(C4 = 0, "", TEXT(A4, "dddd")) -> Wednesday
A5: 45561 | B5: 1 | C5: =IF( ISBLANK($B5),0, B5+C4) -> 12 | D5: ='Goals Data'!$B$3 -> 130 | E5: =WEEKDAY(A5) -> 5 | F5: =IF(C5 = 0, "", TEXT(A5, "dddd")) -> Thursday
A6: 45562 | B6: 2 | C6: =IF( ISBLANK($B6),0, B6+C5) -> 14 | D6: ='Goals Data'!$B$3 -> 130 | E6: =WEEKDAY(A6) -> 6 | F6: =IF(C6 = 0, "", TEXT(A6, "dddd")) -> Friday
A7: 45563 | B7: 8 | C7: =IF( ISBLANK($B7),0, B7+C6) -> 22 | D7: ='Goals Data'!$B$3 -> 130 | E7: =WEEKDAY(A7) -> 7 | F7: =IF(C7 = 0, "", TEXT(A7, "dddd")) -> Saturday
A8: 45564 | B8: 5 | C8: =IF( ISBLANK($B8),0, B8+C7) -> 27 | D8: ='Goals Data'!$B$3 -> 130 | E8: =WEEKDAY(A8) -> 1 | F8: =IF(C8 = 0, "", TEXT(A8, "dddd")) -> Sunday
A9: 45565 | B9: 3 | C9: =IF( ISBLANK($B9),0, B9+C8) -> 30 | D9: ='Goals Data'!$B$3 -> 130 | E9: =WEEKDAY(A9) -> 2 | F9: =IF(C9 = 0, "", TEXT(A9, "dddd")) -> Monday
A10: 45566 | B10: 2 | C10: =IF( ISBLANK($B10),0, B10+C9) -> 32 | D10: ='Goals Data'!$B$3 -> 130 | E10: =WEEKDAY(A10) -> 3 | F10: =IF(C10 = 0, "", TEXT(A10, "dddd")) -> Tuesday
A11: 45567 | B11: 1 | C11: =IF( ISBLANK($B11),0, B11+C10) -> 33 | D11: ='Goals Data'!$B$3 -> 130 | E11: =WEEKDAY(A11) -> 4 | F11: =IF(C11 = 0, "", TEXT(A11, "dddd")) -> Wednesday
A12: 45568 | B12: 1 | C12: =IF( ISBLANK($B12),0, B12+C11) -> 34 | D12: ='Goals Data'!$B$3 -> 130 | E12: =WEEKDAY(A12) -> 5 | F12: =IF(C12 = 0, "", TEXT(A12, "dddd")) -> Thursday
A13: 45569 | B13: 1 | C13: =IF( ISBLANK($B13),0, B13+C12) -> 35 | D13: ='Goals Data'!$B$3 -> 130 | E13: =WEEKDAY(A13) -> 6 | F13: =IF(C13 = 0, "", TEXT(A13, "dddd")) -> Friday
A14: 45570 | B14: 0 | C14: =IF( ISBLANK($B14),0, B14+C13) -> 35 | D14: ='Goals Data'!$B$3 -> 130 | E14: =WEEKDAY(A14) -> 7 | F14: =IF(C14 = 0, "", TEXT(A14, "dddd")) -> Saturday
A15: 45571 | B15: 0 | C15: =IF( ISBLANK($B15),0, B15+C14) -> 35 | D15: ='Goals Data'!$B$3 -> 130 | E15: =WEEKDAY(A15) -> 1 | F15: =IF(C15 = 0, "", TEXT(A15, "dddd")) -> Sunday
... A19: 45575 | B19: 4 | C19: =IF( ISBLANK($B19),0, B19+C18) -> 50 | D19: ='Goals Data'!$B$3 -> 130 | E19: =WEEKDAY(A19) -> 5 | F19: =IF(C19 = 0, "", TEXT(A19, "dddd")) -> Thursday
A20: 45576 | D20: ='Goals Data'!$B$3 -> 130 | E20: =WEEKDAY(A20) -> 6 | F20: =IF(C20 = 0, "", TEXT(A20, "dddd"))
A21: 45577 | D21: ='Goals Data'!$B$3 -> 130 | E21: =WEEKDAY(A21) -> 7 | F21: =IF(C21 = 0, "", TEXT(A21, "dddd"))
A22: 45578 | D22: ='Goals Data'!$B$3 -> 130 | E22: =WEEKDAY(A22) -> 1 | F22: =IF(C22 = 0, "", TEXT(A22, "dddd"))
A23: 45579 | D23: ='Goals Data'!$B$3 -> 130 | E23: =WEEKDAY(A23) -> 2 | F23: =IF(C23 = 0, "", TEXT(A23, "dddd"))
A24: 45580 | D24: ='Goals Data'!$B$3 -> 130 | E24: =WEEKDAY(A24) -> 3 | F24: =IF(C24 = 0, "", TEXT(A24, "dddd"))
A25: 45581 | D25: ='Goals Data'!$B$3 -> 130 | E25: =WEEKDAY(A25) -> 4 | F25: =IF(C25 = 0, "", TEXT(A25, "dddd"))
A26: 45582 | D26: ='Goals Data'!$B$3 -> 130 | E26: =WEEKDAY(A26) -> 5 | F26: =IF(C26 = 0, "", TEXT(A26, "dddd"))
A27: 45583 | D27: ='Goals Data'!$B$3 -> 130 | E27: =WEEKDAY(A27) -> 6 | F27: =IF(C27 = 0, "", TEXT(A27, "dddd"))
A28: 45584 | D28: ='Goals Data'!$B$3 -> 130 | E28: =WEEKDAY(A28) -> 7 | F28: =IF(C28 = 0, "", TEXT(A28, "dddd"))
A29: 45585 | D29: ='Goals Data'!$B$3 -> 130 | E29: =WEEKDAY(A29) -> 1 | F29: =IF(C29 = 0, "", TEXT(A29, "dddd"))
A30: 45586 | D30: ='Goals Data'!$B$3 -> 130 | E30: =WEEKDAY(A30) -> 2 | F30: =IF(C30 = 0, "", TEXT(A30, "dddd"))
A31: 45587 | D31: ='Goals Data'!$B$3 -> 130 | E31: =WEEKDAY(A31) -> 3 | F31: =IF(C31 = 0, "", TEXT(A31, "dddd"))
... A33: 45589 | D33: ='Goals Data'!$B$3 -> 130 | E33: =WEEKDAY(A33) -> 5 | F33: =IF(C33 = 0, "", TEXT(A33, "dddd"))
O81: 3

Sheet Progress Dashboard
B2: Plot the folowing:
C4: 1. KPIs: | I4: KPI: Key Performance Indicators
D5: a. Current Daily avg. hours
D6: b. Required Daily Avg. Hours
C8: 2. Line chart to show total hours vs. target against each date
C9: 3. Show composition analysis of actual vs. deficit hours
I14: ='Progress Summary'!$C$9 -> 2.7777778 | M14: ='Progress Summary'!$C$10 -> 5.7142857
